<?xml version="1.0"?>
<robot xmlns:xacro="http://www.ros.org/wiki/xacro" name="robot">
    
    <!-- add namespace -->
    <xacro:arg name="robot_namespace" default=""/>
    <xacro:property name="robot_namespace"/>    

    <!-- init color -->
    <material name="black">
        <color rgba="0.0 0.0 0.0 1.0"/>
    </material>

    <material name="dark">
        <color rgba="0.3 0.3 0.3 1.0"/>
    </material>

    <material name="light_black">
        <color rgba="0.4 0.4 0.4 1.0"/>
    </material>

    <material name="blue">
        <color rgba="0.0 0.0 0.8 1.0"/>
    </material>

    <material name="green">
        <color rgba="0.0 0.8 0.0 1.0"/>
    </material>

    <material name="grey">
        <color rgba="0.5 0.5 0.5 1.0"/>
    </material>

    <material name="orange">
        <color rgba="1.0 0.4235 0.0392 1.0"/>
    </material>

    <material name="brown">
        <color rgba="0.8706 0.8118 0.7647 1.0"/>
    </material>

    <material name="red">
        <color rgba="0.8 0.0 0.0 1.0"/>
    </material>

    <material name="white">
        <color rgba="1.0 1.0 1.0 1.0"/>
    </material>

    <!-- base_footprint -->
    <link name="base_footprint"/>

    <!-- base_joint -->
    <joint name="base_joint" type="fixed">
        <parent link="base_footprint"/>
        <child link="base_link"/>
        <origin xyz="0.0 0.0 0.010" rpy="0 0 0"/>
    </joint>

    <!-- base_link -->
    <link name="base_link">
        <visual>
            <origin xyz="0 0 0" rpy="0 0 0"/>
            <geometry>
                <!-- <cylinder radius="0.12" length="0.105"/> -->
                <mesh filename="file://$(find robot_description)/meshes/base.stl" scale="0.001 0.001 0.001"/>
            </geometry>
            <material name="light_black"/>
        </visual>

        <collision>
            <origin xyz="0 0 0" rpy="0 0 0"/>
            <geometry>
                <!-- <cylinder radius="0.12" length="0.105"/> -->
                <mesh filename="file://$(find robot_description)/meshes/base.stl" scale="0.001 0.001 0.001"/>
            </geometry>
        </collision>

        <inertial>
            <origin xyz="0 0 0" rpy="0 0 0"/>
            <mass value="8.2573504e-01"/>
            <inertia ixx="2.2124416e-03" ixy="-1.2294101e-05" ixz="3.4938785e-05" iyy="2.1193702e-03" iyz="-5.0120904e-06" izz="2.0064271e-03" />
        </inertial>
    </link>

    <gazebo reference="base_link">
        <material>Gazebo/White</material>
    </gazebo>

    <!-- wheel_right_joint -->
    <joint name="wheel_right_joint" type="continuous">
        <parent link="base_link"/>
        <child link="wheel_right_link"/>
        <origin xyz="0 -0.1021 0.01835" rpy="-1.57 0 0"/>
        <axis xyz="0 0 1"/>
    </joint>

    <!-- wheel_right_link -->
    <link name="wheel_right_link">
        <visual>
            <!-- <origin xyz="0 0 0" rpy="0 0 0"/> -->
            <geometry>
                <!-- <cylinder length="0.018" radius="0.033"/> -->
                <mesh filename="file://$(find robot_description)/meshes/wheel.stl" scale="0.001 0.001 0.001"/>
            </geometry>
            <material name="black"/>
        </visual>

        <collision>
            <!-- <origin xyz="0 0 0" rpy="0 0 0"/> -->
            <geometry>
                <!-- <cylinder length="0.018" radius="0.033"/> -->
                <mesh filename="file://$(find robot_description)/meshes/wheel.stl" scale="0.001 0.001 0.001"/>
            </geometry>
        </collision>

        <inertial>
            <origin xyz="0 0 0" />
            <mass value="2.8498940e-02" />
            <inertia ixx="1.1175580e-05" ixy="-4.2369783e-11" ixz="-5.9381719e-09" iyy="1.1192413e-05" iyz="-1.4400107e-11" izz="2.0712558e-05" />
        </inertial>
    </link>

    <gazebo reference="wheel_right_link">
        <material>Gazebo/FlatBlack</material>
    </gazebo>

    <!-- wheel_left_joint -->
    <joint name="wheel_left_joint" type="continuous">
        <parent link="base_link"/>
        <child link="wheel_left_link"/>
        <origin xyz="0 0.1021 0.01835" rpy="-1.57 0 0"/>
        <axis xyz="0 0 1"/>
    </joint>

    <!-- wheel_left_link -->
    <link name="wheel_left_link">
        <visual>
            <!-- <origin xyz="0 0 0" rpy="0 0 0"/> -->
            <geometry>
                <!-- <cylinder length="0.018" radius="0.033"/> -->
                <mesh filename="file://$(find robot_description)/meshes/wheel.stl" scale="0.001 0.001 0.001"/>
            </geometry>
            <material name="black"/>
        </visual>

        <collision>
            <!-- <origin xyz="0 0 0" rpy="0 0 0"/> -->
            <geometry>
                <!-- <cylinder length="0.018" radius="0.033"/> -->
                <mesh filename="file://$(find robot_description)/meshes/wheel.stl" scale="0.001 0.001 0.001"/>
            </geometry>
        </collision>

        <inertial>
            <origin xyz="0 0 0" />
            <mass value="2.8498940e-02" />
            <inertia ixx="1.1175580e-05" ixy="-4.2369783e-11" ixz="-5.9381719e-09" iyy="1.1192413e-05" iyz="-1.4400107e-11" izz="2.0712558e-05" />
        </inertial>
    </link>

    <gazebo reference="wheel_left_link">
        <material>Gazebo/FlatBlack</material>
    </gazebo>

    <!-- caster_front_joint -->
    <joint name="caster_front_joint" type="fixed">
        <parent link="base_link"/>
        <child link="caster_front_link"/>
        <origin xyz="0.103 0 -0.0098" rpy="0 0 0"/>
        <!-- <axis xyz="0 0 0"/> -->
    </joint>

    <!-- caster_front_link -->
    <link name="caster_front_link">
        <visual>
            <!-- <origin xyz="0 0 0" rpy="0 0 0"/> -->
            <geometry>
                <mesh filename="file://$(find robot_description)/meshes/caster.stl" scale="0.001 0.001 0.001"/>
                <!-- <sphere radius="0.005"/> -->
            </geometry>
            <material name="LightGrey">
                <color rgba="0.7 0.7 0.7 1.0"/>
            </material>
        </visual>
        <collision>
            <!-- <origin xyz="0 0 0" rpy="0 0 0"/> -->
            <geometry>
                <mesh filename="file://$(find robot_description)/meshes/caster.stl" scale="0.001 0.001 0.001"/>
                <!-- <sphere radius="0.005"/> -->
            </geometry>
            <surface>
                <friction>
                    <ode>
                        <mu>1.0</mu>  <!-- 增加摩擦系数 -->
                        <mu2>1.0</mu2>
                        <slip1>0.01</slip1>  <!-- 添加滑动参数 -->
                        <slip2>0.01</slip2>
                    </ode>
                </friction>
            </surface>
        </collision>
        <inertial>
            <origin xyz="0 0 0" />
            <mass value="0.05" /> <!-- 从0.005增加到0.05 -->
            <inertia ixx="0.0001" ixy="0.0" ixz="0.0" iyy="0.0001" iyz="0.0" izz="0.0001" />
        </inertial>
    </link>

    <gazebo reference="caster_front_link">
        <material>Gazebo/FlatBlack</material>
    </gazebo>

    <!-- caster_back_joint -->
    <joint name="caster_back_joint" type="fixed">
        <parent link="base_link"/>
        <child link="caster_back_link"/>
        <origin xyz="-0.103 0 -0.0098" rpy="0 0 0"/>
        <!-- <axis xyz="0 0 0"/> -->
    </joint>

    <!-- caster_back_link -->
    <link name="caster_back_link">
        <visual>
            <!-- <origin xyz="0 0 0" rpy="0 0 0"/> -->
            <geometry>
                <mesh filename="file://$(find robot_description)/meshes/caster.stl" scale="0.001 0.001 0.001"/>
                <!-- <sphere radius="0.005"/> -->
            </geometry>
            <material name="LightGrey">
                <color rgba="0.7 0.7 0.7 1.0"/>
            </material>
        </visual>
        <collision>
            <!-- <origin xyz="0 0 0" rpy="0 0 0"/> -->
            <geometry>
                <mesh filename="file://$(find robot_description)/meshes/caster.stl" scale="0.001 0.001 0.001"/>
                <!-- <sphere radius="0.005"/> -->
            </geometry>
            <surface>
                <friction>
                    <ode>
                        <mu>1.0</mu>  <!-- 增加摩擦系数 -->
                        <mu2>1.0</mu2>
                        <slip1>0.01</slip1>  <!-- 添加滑动参数 -->
                        <slip2>0.01</slip2>
                    </ode>
                </friction>
            </surface>
        </collision>
        <inertial>
            <origin xyz="0 0 0" />
            <mass value="0.05" /> <!-- 从0.005增加到0.05 -->
            <inertia ixx="0.0001" ixy="0.0" ixz="0.0" iyy="0.0001" iyz="0.0" izz="0.0001" />
        </inertial>
    </link>

    <gazebo reference="caster_back_link">
        <material>Gazebo/FlatBlack</material>
    </gazebo>

    <!-- imu_joint -->
    <joint name="imu_joint" type="fixed">
        <parent link="base_link"/>
        <child link="imu_link"/>
        <origin xyz="0 0 0.068" rpy="0 0 0"/>
    </joint>

    <!-- imu_link -->
    <link name="imu_link"/>

    <gazebo reference="imu_link">
        <sensor name="tb3_imu" type="imu">
            <always_on>true</always_on>
            <update_rate>200</update_rate>
            <imu>
                <angular_velocity>
                    <x>
                    <noise type="gaussian">
                        <mean>0.0</mean>
                        <stddev>2e-4</stddev>
                    </noise>
                    </x>
                    <y>
                    <noise type="gaussian">
                        <mean>0.0</mean>
                        <stddev>2e-4</stddev>
                    </noise>
                    </y>
                    <z>
                    <noise type="gaussian">
                        <mean>0.0</mean>
                        <stddev>2e-4</stddev>
                    </noise>
                    </z>
                </angular_velocity>
                <linear_acceleration>
                    <x>
                    <noise type="gaussian">
                        <mean>0.0</mean>
                        <stddev>1.7e-2</stddev>
                    </noise>
                    </x>
                    <y>
                    <noise type="gaussian">
                        <mean>0.0</mean>
                        <stddev>1.7e-2</stddev>
                    </noise>
                    </y>
                    <z>
                    <noise type="gaussian">
                        <mean>0.0</mean>
                        <stddev>1.7e-2</stddev>
                    </noise>
                    </z>
                </linear_acceleration>
            </imu>
            <plugin name="robot_imu" filename="libgazebo_ros_imu_sensor.so">
                <ros>
                    <namespace>$(arg robot_namespace)</namespace>
                    <remapping>~/out:=imu</remapping>
                </ros>
                <initial_orientation_as_reference>false</initial_orientation_as_reference>
            </plugin>
        </sensor>
    </gazebo>

    <!-- scan_joint -->
    <joint name="scan_joint" type="fixed">
        <parent link="base_link"/>
        <child link="base_scan"/>
        <origin xyz="0 0 0.14" rpy="0 0 0"/>
    </joint>

    <!-- base_scan_link -->
    <link name="base_scan">
        <visual>
            <origin xyz="0 0 0.0" rpy="0 0 0"/>
            <geometry>
                <!-- <cylinder length="0.0315" radius="0.055"/> -->
                <mesh filename="file://$(find robot_description)/meshes/lds.stl" scale="0.001 0.001 0.001"/>
            </geometry>
            <material name="dark"/>
        </visual>

        <collision>
            <!-- <origin xyz="0 0 -0.0065" rpy="0 0 0"/> -->
            <geometry>
                <!-- <cylinder length="0.0315" radius="0.055"/> -->
                <mesh filename="file://$(find robot_description)/meshes/lds.stl" scale="0.001 0.001 0.001"/>
            </geometry>
        </collision>

        <inertial>
            <mass value="0.114" />
            <origin xyz="0 0 0" rpy="0 0 0"/>
            <inertia ixx="0.001" ixy="0.0" ixz="0.0" iyy="0.001" iyz="0.0" izz="0.001" />
        </inertial>
    </link>

    <!-- .....................base_scan plugin ................................... -->
    <gazebo reference="base_scan">
        <sensor name="hls_lfcd_lds" type="ray">
            <always_on>true</always_on>
            <visualize>true</visualize>
            <pose>0 0 0 0 0 0</pose>
            <update_rate>100</update_rate>
            <ray>
                <scan>
                    <horizontal>
                        <samples>360</samples>
                        <resolution>1.000000</resolution>
                        <min_angle>0.000000</min_angle>
                        <max_angle>6.28319</max_angle>
                    </horizontal>
                </scan>
                <range>
                    <min>0.080000</min>
                    <max>8.0</max>
                    <resolution>0.001000</resolution>
                </range>
                <noise>
                    <type>gaussian</type>
                    <mean>0.0</mean>
                    <stddev>0.0001</stddev>
                </noise>
            </ray>
            <plugin name="robot_laserscan" filename="libgazebo_ros_ray_sensor.so">
                <ros>
                    <namespace>$(arg robot_namespace)</namespace>
                    <remapping>~/out:=scan</remapping>
                </ros>
                <output_type>sensor_msgs/LaserScan</output_type>
                <frame_name>base_scan</frame_name>
            </plugin>
        </sensor>
    </gazebo>

    <!-- .....................diff drive plugin ................................... -->
    <gazebo>
        <plugin name="robot_diff_drive" filename="libgazebo_ros_diff_drive.so">
            <ros>
                <namespace>$(arg robot_namespace)</namespace>
                <remapping>cmd_vel:=cmd_vel</remapping>
                <remapping>odom:=odom</remapping>
            </ros>
            <legacy_mode>false</legacy_mode>
            <update_rate>50.0</update_rate>
            <left_joint>wheel_left_joint</left_joint>
            <right_joint>wheel_right_joint</right_joint>
            <wheel_separation>0.2042</wheel_separation>
            <wheel_diameter>0.066</wheel_diameter>
            <robot_base_frame>base_footprint</robot_base_frame>
            <max_wheel_torque>10</max_wheel_torque>
            <max_wheel_acceleration>0.5</max_wheel_acceleration>
            <command_topic>cmd_vel</command_topic>
            <odometry_topic>odom</odometry_topic>
            <odometry_frame>odom</odometry_frame>
            <publish_odom>true</publish_odom>
            <publish_odom_tf>true</publish_odom_tf>
            <publish_wheel_tf>false</publish_wheel_tf>
            <!-- Odometry source, 0 for ENCODER, 1 for WORLD, defaults to WORLD -->
            <odometry_source>0</odometry_source>
        </plugin>
    </gazebo>

    <!--............................... ground truth plugin .............................-->
    <gazebo>
        <plugin name="p3d_base_controller" filename="libgazebo_ros_p3d.so">
            <ros>
                <namespace>$(arg robot_namespace)</namespace>
                <remapping>odom:=p3d_ground_truth</remapping>
            </ros>
            <always_on>true</always_on>
            <update_rate>50.0</update_rate>
            <body_name>base_footprint</body_name>
            <gaussian_noise>0.00</gaussian_noise>
            <frame_name>map</frame_name>
        </plugin>
    </gazebo>

    <!-- 为轮子添加对称的Gazebo物理属性 -->
    <gazebo reference="wheel_left_link">
        <material>Gazebo/FlatBlack</material>
        <kp>1000000.0</kp>
        <kd>100.0</kd>
        <mu1>1.5</mu1>
        <mu2>1.5</mu2>
        <minDepth>0.001</minDepth>
        <maxVel>1.0</maxVel>
    </gazebo>

    <gazebo reference="wheel_right_link">
        <material>Gazebo/FlatBlack</material>
        <kp>1000000.0</kp>
        <kd>100.0</kd>
        <mu1>1.5</mu1>
        <mu2>1.5</mu2>
        <minDepth>0.001</minDepth>
        <maxVel>1.0</maxVel>
    </gazebo>

</robot>
